# 10.23

> 考虑下面的代码。输出是什么，为什么？

```javascript
(function (){
    try{
        throw new Error();
    }catch(x){
        var x = 1,y = 2;
        console.log(x);
    }
    console.log(x);
    console.log(y);
})();

```

---

```
1
undefined
2
```

var语句被挂起（没有它们的值初始化）到它所属的全局或函数作用域的顶部，即使它位于with或catch块内。但是，错误的标识符只在catch块内部可见。它相当于：

```javascript
(function (){
    var x,y; //outer and hoisted
    try{
        throw new Error();
    }catch(x /*inner*/){
        x = 1;//inner x,not the outer one
        y = 2;//there is only one y,which is in the outer scope
        console.log(x /*inner*/);
    }
    console.log(x);
    console.log(y);
})();
```

